try{
    let a = 0;
    console.log("Executed successfully")
}catch(err){
    console.log("Error occured")
}finally{
    console.log("finally clause executed even if any error occured");
}
